Workbook

Sheet Sales_Data
A1: Order_ID | B1: Date | C1: Month | D1: City | E1: Category | F1: Product | G1: Salesperson | H1: Quantity | I1: Unit_Price_PKR | J1: Discount_% | K1: Revenue_PKR | L1: Cost_PKR | M1: Profit_PKR
A2: ORD-1001 | B2: 45720 | C2: March | D2: Lahore | E2: Groceries | F2: Desi Ghee | G2: Ayesha Malik | H2: 5 | I2: 1800 | J2: 0 | K2: =H2*I2*(1-J2/100) -> 9000 | L2: =K2*0.69 -> 6210 | M2: =K2-L2 -> 2790
A3: ORD-1002 | B3: 45719 | C3: March | D3: Rawalpindi | E3: Furniture | F3: Sofa Set | G3: Ahmed Ali | H3: 3 | I3: 85000 | J3: 5 | K3: =H3*I3*(1-J3/100) -> 242250 | L3: =K3*0.6 -> 145350 | M3: =K3-L3 -> 96900
A4: ORD-1003 | B4: 45717 | C4: March | D4: Rawalpindi | E4: Electronics | F4: Smart Watch | G4: Zain Hussain | H4: 8 | I4: 22000 | J4: 15 | K4: =H4*I4*(1-J4/100) -> 149600 | L4: =K4*0.67 -> 100232 | M4: =K4-L4 -> 49368
A5: ORD-1004 | B5: 45682 | C5: January | D5: Karachi | E5: Furniture | F5: Wardrobe | G5: Bilal Sheikh | H5: 5 | I5: 62000 | J5: 5 | K5: =H5*I5*(1-J5/100) -> 294500 | L5: =K5*0.74 -> 217930 | M5: =K5-L5 -> 76570
A6: ORD-1005 | B6: 45692 | C6: February | D6: Lahore | E6: Furniture | F6: Sofa Set | G6: Sana Iqbal | H6: 12 | I6: 85000 | J6: 20 | K6: =H6*I6*(1-J6/100) -> 816000 | L6: =K6*0.6 -> 489600 | M6: =K6-L6 -> 326400
A7: ORD-1006 | B7: 45681 | C7: January | D7: Faisalabad | E7: Cosmetics | F7: Skin Cream | G7: Zain Hussain | H7: 3 | I7: 1200 | J7: 20 | K7: =H7*I7*(1-J7/100) -> 2880 | L7: =K7*0.61 -> 1756.8 | M7: =K7-L7 -> 1123.2
A8: ORD-1007 | B8: 45736 | C8: March | D8: Islamabad | E8: Cosmetics | F8: Lipstick | G8: Fatima Khan | H8: 2 | I8: 800 | J8: 5 | K8: =H8*I8*(1-J8/100) -> 1520 | L8: =K8*0.7 -> 1064 | M8: =K8-L8 -> 456
A9: ORD-1008 | B9: 45685 | C9: January | D9: Karachi | E9: Clothing | F9: T-Shirt | G9: Bilal Sheikh | H9: 15 | I9: 900 | J9: 10 | K9: =H9*I9*(1-J9/100) -> 12150 | L9: =K9*0.58 -> 7047 | M9: =K9-L9 -> 5103
A10: ORD-1009 | B10: 45695 | C10: February | D10: Islamabad | E10: Clothing | F10: Dupatta | G10: Usman Raza | H10: 18 | I10: 700 | J10: 5 | K10: =H10*I10*(1-J10/100) -> 11970 | L10: =K10*0.58 -> 6942.6 | M10: =K10-L10 -> 5027.4
A11: ORD-1010 | B11: 45697 | C11: February | D11: Rawalpindi | E11: Electronics | F11: Headphones | G11: Ahmed Ali | H11: 8 | I11: 8500 | J11: 0 | K11: =H11*I11*(1-J11/100) -> 68000 | L11: =K11*0.71 -> 48280 | M11: =K11-L11 -> 19720
A12: ORD-1011 | B12: 45697 | C12: February | D12: Lahore | E12: Electronics | F12: Smart Watch | G12: Sana Iqbal | H12: 7 | I12: 22000 | J12: 15 | K12: =H12*I12*(1-J12/100) -> 130900 | L12: =K12*0.63 -> 82467 | M12: =K12-L12 -> 48433
A13: ORD-1012 | B13: 45731 | C13: March | D13: Karachi | E13: Groceries | F13: Desi Ghee | G13: Ayesha Malik | H13: 18 | I13: 1800 | J13: 20 | K13: =H13*I13*(1-J13/100) -> 25920 | L13: =K13*0.6 -> 15552 | M13: =K13-L13 -> 10368
A14: ORD-1013 | B14: 45730 | C14: March | D14: Rawalpindi | E14: Furniture | F14: Wardrobe | G14: Ayesha Malik | H14: 5 | I14: 62000 | J14: 20 | K14: =H14*I14*(1-J14/100) -> 248000 | L14: =K14*0.65 -> 161200 | M14: =K14-L14 -> 86800
A15: ORD-1014 | B15: 45685 | C15: January | D15: Lahore | E15: Electronics | F15: Laptop | G15: Zain Hussain | H15: 20 | I15: 120000 | J15: 0 | K15: =H15*I15*(1-J15/100) -> 2400000 | L15: =K15*0.63 -> 1512000 | M15: =K15-L15 -> 888000
A16: ORD-1015 | B16: 45731 | C16: March | D16: Rawalpindi | E16: Groceries | F16: Sugar | G16: Ahmed Ali | H16: 4 | I16: 200 | J16: 20 | K16: =H16*I16*(1-J16/100) -> 640 | L16: =K16*0.7 -> 448 | M16: =K16-L16 -> 192
A17: ORD-1016 | B17: 45727 | C17: March | D17: Lahore | E17: Groceries | F17: Cooking Oil | G17: Usman Raza | H17: 15 | I17: 650 | J17: 0 | K17: =H17*I17*(1-J17/100) -> 9750 | L17: =K17*0.74 -> 7215 | M17: =K17-L17 -> 2535
A18: ORD-1017 | B18: 45725 | C18: March | D18: Rawalpindi | E18: Electronics | F18: Smart Watch | G18: Fatima Khan | H18: 10 | I18: 22000 | J18: 20 | K18: =H18*I18*(1-J18/100) -> 176000 | L18: =K18*0.67 -> 117920 | M18: =K18-L18 -> 58080
A19: ORD-1018 | B19: 45669 | C19: January | D19: Karachi | E19: Cosmetics | F19: Face Wash | G19: Ahmed Ali | H19: 20 | I19: 450 | J19: 10 | K19: =H19*I19*(1-J19/100) -> 8100 | L19: =K19*0.65 -> 5265 | M19: =K19-L19 -> 2835
A20: ORD-1019 | B20: 45669 | C20: January | D20: Islamabad | E20: Electronics | F20: Mobile Phone | G20: Ayesha Malik | H20: 19 | I20: 45000 | J20: 0 | K20: =H20*I20*(1-J20/100) -> 855000 | L20: =K20*0.57 -> 487350 | M20: =K20-L20 -> 367650
A21: ORD-1020 | B21: 45715 | C21: February | D21: Lahore | E21: Cosmetics | F21: Lipstick | G21: Usman Raza | H21: 16 | I21: 800 | J21: 20 | K21: =H21*I21*(1-J21/100) -> 10240 | L21: =K21*0.58 -> 5939.2 | M21: =K21-L21 -> 4300.8
A22: ORD-1021 | B22: 45744 | C22: March | D22: Rawalpindi | E22: Furniture | F22: Dining Table | G22: Kamran Butt | H22: 7 | I22: 45000 | J22: 10 | K22: =H22*I22*(1-J22/100) -> 283500 | L22: =K22*0.63 -> 178605 | M22: =K22-L22 -> 104895
A23: ORD-1022 | B23: 45737 | C23: March | D23: Islamabad | E23: Furniture | F23: Study Chair | G23: Hira Baig | H23: 4 | I23: 12000 | J23: 5 | K23: =H23*I23*(1-J23/100) -> 45600 | L23: =K23*0.59 -> 26904 | M23: =K23-L23 -> 18696
A24: ORD-1023 | B24: 45689 | C24: February | D24: Rawalpindi | E24: Cosmetics | F24: Lipstick | G24: Nadia Aslam | H24: 8 | I24: 800 | J24: 0 | K24: =H24*I24*(1-J24/100) -> 6400 | L24: =K24*0.56 -> 3584 | M24: =K24-L24 -> 2816
A25: ORD-1024 | B25: 45718 | C25: March | D25: Karachi | E25: Clothing | F25: Shalwar Kameez | G25: Sana Iqbal | H25: 3 | I25: 2500 | J25: 20 | K25: =H25*I25*(1-J25/100) -> 6000 | L25: =K25*0.6 -> 3600 | M25: =K25-L25 -> 2400
A26: ORD-1025 | B26: 45732 | C26: March | D26: Karachi | E26: Cosmetics | F26: Lipstick | G26: Nadia Aslam | H26: 19 | I26: 800 | J26: 15 | K26: =H26*I26*(1-J26/100) -> 12920 | L26: =K26*0.6 -> 7752 | M26: =K26-L26 -> 5168
A27: ORD-1026 | B27: 45714 | C27: February | D27: Faisalabad | E27: Electronics | F27: Mobile Phone | G27: Fatima Khan | H27: 14 | I27: 45000 | J27: 10 | K27: =H27*I27*(1-J27/100) -> 567000 | L27: =K27*0.63 -> 357210 | M27: =K27-L27 -> 209790
A28: ORD-1027 | B28: 45716 | C28: February | D28: Lahore | E28: Clothing | F28: Shalwar Kameez | G28: Zain Hussain | H28: 11 | I28: 2500 | J28: 0 | K28: =H28*I28*(1-J28/100) -> 27500 | L28: =K28*0.6 -> 16500 | M28: =K28-L28 -> 11000
A29: ORD-1028 | B29: 45675 | C29: January | D29: Faisalabad | E29: Electronics | F29: Charger | G29: Usman Raza | H29: 9 | I29: 1500 | J29: 15 | K29: =H29*I29*(1-J29/100) -> 11475 | L29: =K29*0.6 -> 6885 | M29: =K29-L29 -> 4590
A30: ORD-1029 | B30: 45672 | C30: January | D30: Rawalpindi | E30: Clothing | F30: Shalwar Kameez | G30: Kamran Butt | H30: 1 | I30: 2500 | J30: 0 | K30: =H30*I30*(1-J30/100) -> 2500 | L30: =K30*0.74 -> 1850 | M30: =K30-L30 -> 650
A31: ORD-1030 | B31: 45663 | C31: January | D31: Faisalabad | E31: Furniture | F31: Bed Frame | G31: Ayesha Malik | H31: 13 | I31: 38000 | J31: 0 | K31: =H31*I31*(1-J31/100) -> 494000 | L31: =K31*0.58 -> 286520 | M31: =K31-L31 -> 207480
A32: ORD-1031 | B32: 45670 | C32: January | D32: Islamabad | E32: Furniture | F32: Wardrobe | G32: Zain Hussain | H32: 18 | I32: 62000 | J32: 15 | K32: =H32*I32*(1-J32/100) -> 948600 | L32: =K32*0.58 -> 550188 | M32: =K32-L32 -> 398412
A33: ORD-1032 | B33: 45695 | C33: February | D33: Lahore | E33: Cosmetics | F33: Face Wash | G33: Ahmed Ali | H33: 11 | I33: 450 | J33: 0 | K33: =H33*I33*(1-J33/100) -> 4950 | L33: =K33*0.56 -> 2772 | M33: =K33-L33 -> 2178
A34: ORD-1033 | B34: 45705 | C34: February | D34: Rawalpindi | E34: Electronics | F34: Mobile Phone | G34: Kamran Butt | H34: 3 | I34: 45000 | J34: 5 | K34: =H34*I34*(1-J34/100) -> 128250 | L34: =K34*0.56 -> 71820 | M34: =K34-L34 -> 56430
A35: ORD-1034 | B35: 45679 | C35: January | D35: Karachi | E35: Furniture | F35: Sofa Set | G35: Nadia Aslam | H35: 8 | I35: 85000 | J35: 20 | K35: =H35*I35*(1-J35/100) -> 544000 | L35: =K35*0.67 -> 364480 | M35: =K35-L35 -> 179520
A36: ORD-1035 | B36: 45719 | C36: March | D36: Faisalabad | E36: Cosmetics | F36: Face Wash | G36: Kamran Butt | H36: 11 | I36: 450 | J36: 10 | K36: =H36*I36*(1-J36/100) -> 4455 | L36: =K36*0.59 -> 2628.45 | M36: =K36-L36 -> 1826.55
A37: ORD-1036 | B37: 45727 | C37: March | D37: Karachi | E37: Groceries | F37: Cooking Oil | G37: Usman Raza | H37: 10 | I37: 650 | J37: 15 | K37: =H37*I37*(1-J37/100) -> 5525 | L37: =K37*0.61 -> 3370.25 | M37: =K37-L37 -> 2154.75
A38: ORD-1037 | B38: 45658 | C38: January | D38: Faisalabad | E38: Cosmetics | F38: Face Wash | G38: Fatima Khan | H38: 3 | I38: 450 | J38: 20 | K38: =H38*I38*(1-J38/100) -> 1080 | L38: =K38*0.59 -> 637.2 | M38: =K38-L38 -> 442.8
A39: ORD-1038 | B39: 45693 | C39: February | D39: Islamabad | E39: Clothing | F39: Kurta | G39: Sana Iqbal | H39: 10 | I39: 1800 | J39: 5 | K39: =H39*I39*(1-J39/100) -> 17100 | L39: =K39*0.64 -> 10944 | M39: =K39-L39 -> 6156
A40: ORD-1039 | B40: 45739 | C40: March | D40: Islamabad | E40: Cosmetics | F40: Face Wash | G40: Ahmed Ali | H40: 18 | I40: 450 | J40: 10 | K40: =H40*I40*(1-J40/100) -> 7290 | L40: =K40*0.74 -> 5394.6 | M40: =K40-L40 -> 1895.4
...

Sheet Summary
B2: 🛍️ Pakistan Retail Sales — Q1 2025 Summary
B4: Revenue by Category (PKR) | F4: Revenue by City (PKR)
B5: Category | C5: Total Revenue | D5: % Share | F5: City | G5: Total Revenue | H5: Total Profit
B6: Clothing | C6: =SUMIF(Sales_Data!E:E,B6,Sales_Data!K:K) -> 672905 | D6: =C6/SUM(C6:C10) -> 0.019850529 | F6: Lahore | G6: =SUMIF(Sales_Data!D:D,F6,Sales_Data!K:K) -> 7122941 | H6: =SUMIF(Sales_Data!D:D,F6,Sales_Data!M:M) -> 2512878.2
B7: Electronics | C7: =SUMIF(Sales_Data!E:E,B7,Sales_Data!K:K) -> 15241750 | D7: =C7/SUM(C6:C10) -> 0.44962782 | F7: Karachi | G7: =SUMIF(Sales_Data!D:D,F7,Sales_Data!K:K) -> 7673557.5 | H7: =SUMIF(Sales_Data!D:D,F7,Sales_Data!M:M) -> 2555583.5
B8: Groceries | C8: =SUMIF(Sales_Data!E:E,B8,Sales_Data!K:K) -> 195037 | D8: =C8/SUM(C6:C10) -> 0.0057535428 | F8: Islamabad | G8: =SUMIF(Sales_Data!D:D,F8,Sales_Data!K:K) -> 7542968 | H8: =SUMIF(Sales_Data!D:D,F8,Sales_Data!M:M) -> 2672484.8
B9: Furniture | C9: =SUMIF(Sales_Data!E:E,B9,Sales_Data!K:K) -> 17343700 | D9: =C9/SUM(C6:C10) -> 0.51163482 | F9: Faisalabad | G9: =SUMIF(Sales_Data!D:D,F9,Sales_Data!K:K) -> 4927067.5 | H9: =SUMIF(Sales_Data!D:D,F9,Sales_Data!M:M) -> 1783135.4
B10: Cosmetics | C10: =SUMIF(Sales_Data!E:E,B10,Sales_Data!K:K) -> 445200 | D10: =C10/SUM(C6:C10) -> 0.013133289 | F10: Rawalpindi | G10: =SUMIF(Sales_Data!D:D,F10,Sales_Data!K:K) -> 6632058 | H10: =SUMIF(Sales_Data!D:D,F10,Sales_Data!M:M) -> 2444508.6
B11: TOTAL | C11: =SUM(C6:C10) -> 33898592
B13: Monthly Revenue
B14: Month | C14: Revenue | D14: Profit
B15: January | C15: =SUMIF(Sales_Data!C:C,B15,Sales_Data!K:K) -> 15111715 | D15: =SUMIF(Sales_Data!C:C,B15,Sales_Data!M:M) -> 5371570.8
B16: February | C16: =SUMIF(Sales_Data!C:C,B16,Sales_Data!K:K) -> 9574198.5 | D16: =SUMIF(Sales_Data!C:C,B16,Sales_Data!M:M) -> 3382188.2
B17: March | C17: =SUMIF(Sales_Data!C:C,B17,Sales_Data!K:K) -> 9212678.5 | D17: =SUMIF(Sales_Data!C:C,B17,Sales_Data!M:M) -> 3214831.5

Sheet Practice_Functions
B2: 📊 Excel Functions Practice Sheet
B4: INSTRUCTIONS: Try to write these formulas yourself in column E. Answers are in column F.
B6: Function | C6: Task | D6: Your Answer → | F6: Formula to Use
B7: SUMIF | C7: Total Revenue from Lahore | D7: ← Write here | F7: =SUMIF(Sales_Data!D:D,"Lahore",Sales_Data!K:K) -> 7122941
B8: COUNTIF | C8: Count orders in Clothing category | D8: ← Write here | F8: =COUNTIF(Sales_Data!E:E,"Clothing") -> 39
B9: AVERAGEIF | C9: Average profit for Electronics | D9: ← Write here | F9: =AVERAGEIF(Sales_Data!E:E,"Electronics",Sales_Data!M:M) -> 128672.04
B10: SUMIFS | C10: Total revenue from Karachi + Clothing | D10: ← Write here | F10: =SUMIFS(Sales_Data!K:K,Sales_Data!D:D,"Karachi",Sales_Data!E:E,"Clothing") -> 147650
B11: VLOOKUP | C11: Find Unit Price for 'Laptop' | D11: ← Write here | F11: =VLOOKUP("Laptop",Sales_Data!F:I,4,0) -> 120000
B12: MAX | C12: Highest single order revenue | D12: ← Write here | F12: =MAX(Sales_Data!K:K) -> 2400000
B13: MIN | C13: Lowest single order revenue | D13: ← Write here | F13: =MIN(Sales_Data!K:K) -> 510
B14: AVERAGE | C14: Average order revenue | D14: ← Write here | F14: =AVERAGE(Sales_Data!K:K) -> 169492.96
B15: IF | C15: Flag profit > 10000 as 'High' else 'Low' | D15: ← Write here | F15: =IF(Sales_Data!M2>10000,"High","Low") -> Low
B16: COUNTA | C16: Count total orders | D16: ← Write here | F16: =COUNTA(Sales_Data!A:A)-1 -> 200
